Workbook

Sheet Rekap Rata Rata keseluruhan
A1: Model | B1: Chunking | C1: Top K | D1: Faithfulness | E1: Answer_Relevancy | F1: Context_Precision | G1: Context_Recall
A2: LaBSE | B2: 32 | C2: 3 | D2: =ROUND(AVERAGE('Labse Top K=3 Chunk = 32'!E1:E81), 4) -> 0.6197 | E2: =ROUND(AVERAGE('Labse Top K=3 Chunk = 32'!F1:F81),4) -> 0.6622 | F2: =ROUND(AVERAGE('Labse Top K=3 Chunk = 32'!G1:G81),4) -> 0.5708 | G2: =ROUND(AVERAGE('Labse Top K=3 Chunk = 32'!H1:H81),4) -> 0.6389
A3: LaBSE | B3: 32 | C3: 5 | D3: =ROUND(AVERAGE('Labse Top K=5 Chunk = 32'!E1:E81), 4) -> 0.6125 | E3: =ROUND(AVERAGE('Labse Top K=5 Chunk = 32'!F1:F81), 4) -> 0.7231 | F3: =ROUND(AVERAGE('Labse Top K=5 Chunk = 32'!G1:G81), 4) -> 0.5948 | G3: =ROUND(AVERAGE('Labse Top K=5 Chunk = 32'!H1:H81), 4) -> 0.7326
A4: LaBSE | B4: 64 | C4: 3 | D4: =ROUND(AVERAGE('Labse Top K=3 Chunk = 64'!E1:E81),4) -> 0.601 | E4: =AVERAGE('Labse Top K=3 Chunk = 64'!F1:F81) -> 0.6182625 | F4: =AVERAGE('Labse Top K=3 Chunk = 64'!G1:G81) -> 0.5759625 | G4: =AVERAGE('Labse Top K=3 Chunk = 64'!H1:H81) -> 0.691675
A5: LaBSE | B5: 64 | C5: 5 | D5: =ROUND(AVERAGE('Labse Top K=5 Chunk = 64'!E1:E81), 4) -> 0.6201 | E5: =ROUND(AVERAGE('Labse Top K=5 Chunk = 64'!F1:F81), 4) -> 0.6538 | F5: =ROUND(AVERAGE('Labse Top K=5 Chunk = 64'!G1:G81), 4) -> 0.6122 | G5: =ROUND(AVERAGE('Labse Top K=5 Chunk = 64'!H1:H81), 4) -> 0.7232
A6: BGE-M3 | B6: 32 | C6: 3 | D6: =ROUND(AVERAGE('BGE-M3 Top K = 3 , Chunk 32'!E2:E81),4) -> 0.7034 | E6: =ROUND(AVERAGE('BGE-M3 Top K = 3 , Chunk 32'!F2:F81),4) -> 0.824 | F6: =ROUND(AVERAGE('BGE-M3 Top K = 3 , Chunk 32'!G2:G81),4) -> 0.801 | G6: =ROUND(AVERAGE('BGE-M3 Top K = 3 , Chunk 32'!H2:H81),4) -> 0.6744
A7: BGE-M3 | B7: 32 | C7: 5 | D7: =ROUND(AVERAGE('BGE-M3 Top K = 5 , Chunk 32'!E1:E81),4) -> 0.7621 | E7: =ROUND(AVERAGE('BGE-M3 Top K = 5 , Chunk 32'!F1:F81),4) -> 0.8566 | F7: =ROUND(AVERAGE('BGE-M3 Top K = 5 , Chunk 32'!G1:G81),4) -> 0.8008 | G7: =ROUND(AVERAGE('BGE-M3 Top K = 5 , Chunk 32'!H1:H81),4) -> 0.702
A8: BGE-M3 | B8: 64 | C8: 3 | D8: =ROUND(AVERAGE('BGE-M3 Top K = 3 , Chunk 64'!E2:E81),4) -> 0.6878 | E8: =ROUND(AVERAGE('BGE-M3 Top K = 3 , Chunk 64'!F2:F81),4) -> 0.814 | F8: =ROUND(AVERAGE('BGE-M3 Top K = 3 , Chunk 64'!G2:G81),4) -> 0.8291 | G8: =ROUND(AVERAGE('BGE-M3 Top K = 3 , Chunk 64'!H2:H81),4) -> 0.764
A9: BGE-M3 | B9: 64 | C9: 5 | D9: =ROUND(AVERAGE('BGE-M3 Top K = 5 , Chunk 64'!E2:E81),4) -> 0.7224 | E9: =ROUND(AVERAGE('BGE-M3 Top K = 5 , Chunk 64'!F2:F81),4) -> 0.8459 | F9: =ROUND(AVERAGE('BGE-M3 Top K = 5 , Chunk 64'!G2:G81),4) -> 0.856 | G9: =ROUND(AVERAGE('BGE-M3 Top K = 5 , Chunk 64'!H2:H81),4) -> 0.8132
A14: Question Type | B14: Chunking | C14: Top-K | D14: Faithfulness | E14: Answer Relevancy | F14: Context Precision | G14: Context Recall
A15: Trend Analysis | B15: 32 | C15: 3 | D15: =ROUND(AVERAGE(E35,E51),4) -> 0.6244 | E15: =ROUND(AVERAGE(F35,F51),4) -> 0.8222 | F15: =ROUND(AVERAGE(G35,G51),4) -> 0.7458 | G15: =ROUND(AVERAGE(H35,H51),4) -> 0.7289
A16: Gap Detection | B16: 32 | C16: 3 | D16: =ROUND(AVERAGE(E36,E52),4) -> 0.7117 | E16: =ROUND(AVERAGE(F36,F52),4) -> 0.7454 | F16: =ROUND(AVERAGE(G36,G52),4) -> 0.7416 | G16: =ROUND(AVERAGE(H36,H52),4) -> 0.7094
A17: Comparative Synthesis | B17: 32 | C17: 3 | D17: =ROUND(AVERAGE(E37,E53),4) -> 0.6516 | E17: =ROUND(AVERAGE(F37,F53),4) -> 0.77 | F17: =ROUND(AVERAGE(G37,G53),4) -> 0.6813 | G17: =ROUND(AVERAGE(H37,H53),4) -> 0.5079
A18: Evidence-based QA | B18: 32 | C18: 3 | D18: =ROUND(AVERAGE(E38,E54),4) -> 0.6587 | E18: =ROUND(AVERAGE(F38,F54),4) -> 0.6352 | F18: =ROUND(AVERAGE(G38,G54),4) -> 0.575 | G18: =ROUND(AVERAGE(H38,H54),4) -> 0.6807
A19: Trend Analysis | B19: 32 | C19: 5 | D19: =ROUND(AVERAGE(E39,E55),4) -> 0.7558 | E19: =ROUND(AVERAGE(F39,F55),4) -> 0.8059 | F19: =ROUND(AVERAGE(G39,G55),4) -> 0.7173 | G19: =ROUND(AVERAGE(H39,H55),4) -> 0.7243
A20: Gap Detection | B20: 32 | C20: 5 | D20: =ROUND(AVERAGE(E40,E56),4) -> 0.7413 | E20: =ROUND(AVERAGE(F40,F56),4) -> 0.7326 | F20: =ROUND(AVERAGE(G40,G56),4) -> 0.7803 | G20: =ROUND(AVERAGE(H40,H56),4) -> 0.754
A21: Comparative Synthesis | B21: 32 | C21: 5 | D21: =ROUND(AVERAGE(E41,E57),4) -> 0.5977 | E21: =ROUND(AVERAGE(F41,F57),4) -> 0.8386 | F21: =ROUND(AVERAGE(G41,G57),4) -> 0.7274 | G21: =ROUND(AVERAGE(H41,H57),4) -> 0.5908
A22: Evidence-based QA | B22: 32 | C22: 5 | D22: =ROUND(AVERAGE(E42,E58),4) -> 0.6545 | E22: =ROUND(AVERAGE(F42,F58),4) -> 0.7824 | F22: =ROUND(AVERAGE(G42,G58),4) -> 0.5664 | G22: =ROUND(AVERAGE(H42,H58),4) -> 0.7492
A23: Trend Analysis | B23: 64 | C23: 3 | D23: =ROUND(AVERAGE(E43,E59),4) -> 0.6096 | E23: =ROUND(AVERAGE(F43,F59),4) -> 0.7707 | F23: =ROUND(AVERAGE(G43,G59),4) -> 0.7187 | G23: =ROUND(AVERAGE(H43,H59),4) -> 0.8024
A24: Gap Detection | B24: 64 | C24: 3 | D24: =ROUND(AVERAGE(E44,E60),4) -> 0.6773 | E24: =ROUND(AVERAGE(F44,F60),4) -> 0.6593 | F24: =ROUND(AVERAGE(G44,G60),4) -> 0.7479 | G24: =ROUND(AVERAGE(H44,H60),4) -> 0.7245
A25: Comparative Synthesis | B25: 64 | C25: 3 | D25: =ROUND(AVERAGE(E45,E61),4) -> 0.647 | E25: =ROUND(AVERAGE(F45,F61),4) -> 0.8355 | F25: =ROUND(AVERAGE(G45,G61),4) -> 0.75 | G25: =ROUND(AVERAGE(H45,H61),4) -> 0.5907
A26: Evidence-based QA | B26: 64 | C26: 3 | D26: =ROUND(AVERAGE(E46,E62),4) -> 0.6439 | E26: =ROUND(AVERAGE(F46,F62),4) -> 0.5991 | F26: =ROUND(AVERAGE(G46,G62),4) -> 0.5937 | G26: =ROUND(AVERAGE(H46,H62),4) -> 0.6986
... A30: Evidence-based QA | B30: 64 | C30: 5 | D30: =ROUND(AVERAGE(E50,E66),4) -> 0.7206 | E30: =ROUND(AVERAGE(F50,F66),4) -> 0.6462 | F30: =ROUND(AVERAGE(G50,G66),4) -> 0.5946 | G30: =ROUND(AVERAGE(H50,H66),4) -> 0.7324
A34: Model | B34: Question Type | C34: Chunking | D34: Top-K | E34: Faithfulness | F34: Answer Relevancy | G34: Context Precision | H34: Context Recall
A35: LaBSE | B35: Trend Analysis | C35: 32 | D35: 3 | E35: =IFERROR(__xludf.DUMMYFUNCTION("IFERROR( ROUND( AVERAGE( FILTER( 'Labse Top K=3 Chunk = 32'!E:E, TRIM('Labse Top K=3 Chunk = 32'!J:J)=""Trend Analysis"" ) ), 4), ""Data tidak ada"" ) "),0.6127) -> 0.6127 | F35: =IFERROR(__xludf.DUMMYFUNCTION("IFERROR( ROUND( AVERAGE( FILTER( 'Labse Top K=3 Chunk = 32'!F:F, TRIM('Labse Top K=3 Chunk = 32'!J:J)=""Trend Analysis"" ) ), 4), ""Data tidak ada"" ) "),0.7325) -> 0.7325 | G35: =IFERROR(__xludf.DUMMYFUNCTION("IFERROR( ROUND( AVERAGE( FILTER( 'Labse Top K=3 Chunk = 32'!G:G, TRIM('Labse Top K=3 Chunk = 32'!J:J)=""Trend Analysis"" ) ), 4), ""Data tidak ada"" ) "),0.5957) -> 0.5957 | H35: =IFERROR(__xludf.DUMMYFUNCTION("IFERROR( ROUND( AVERAGE( FILTER( 'Labse Top K=3 Chunk = 32'!H:H, TRIM('Labse Top K=3 Chunk = 32'!J:J)=""Trend Analysis"" ) ), 4), ""Data tidak ada"" ) "),0.7044) -> 0.7044
A36: LaBSE | B36: Gap Detection | C36: 32 | D36: 3 | E36: =IFERROR(__xludf.DUMMYFUNCTION("IFERROR( ROUND( AVERAGE( FILTER( 'Labse Top K=3 Chunk = 32'!E:E, TRIM('Labse Top K=3 Chunk = 32'!J:J)=""Gap Detection"" ) ), 4), ""Data tidak ada"" ) "),0.6613) -> 0.6613 | F36: =IFERROR(__xludf.DUMMYFUNCTION("IFERROR( ROUND( AVERAGE( FILTER( 'Labse Top K=3 Chunk = 32'!F:F, TRIM('Labse Top K=3 Chunk = 32'!J:J)=""Gap Detection"" ) ), 4), ""Data tidak ada"" ) "),0.7531) -> 0.7531 | G36: =IFERROR(__xludf.DUMMYFUNCTION("IFERROR( ROUND( AVERAGE( FILTER( 'Labse Top K=3 Chunk = 32'!G:G, TRIM('Labse Top K=3 Chunk = 32'!J:J)=""Gap Detection"" ) ), 4), ""Data tidak ada"" ) "),0.6499) -> 0.6499 | H36: =IFERROR(__xludf.DUMMYFUNCTION("IFERROR( ROUND( AVERAGE( FILTER( 'Labse Top K=3 Chunk = 32'!H:H, TRIM('Labse Top K=3 Chunk = 32'!J:J)=""Gap Detection"" ) ), 4), ""Data tidak ada"" ) "),0.6894) -> 0.6894
A37: LaBSE | B37: Comparative Synthesis | C37: 32 | D37: 3 | E37: =IFERROR(__xludf.DUMMYFUNCTION("IFERROR( ROUND( AVERAGE( FILTER( 'Labse Top K=3 Chunk = 32'!E:E, TRIM('Labse Top K=3 Chunk = 32'!J:J)=""Comparative Synthesis"" ) ), 4), ""Data tidak ada"" ) "),0.6087) -> 0.6087 | F37: =IFERROR(__xludf.DUMMYFUNCTION("IFERROR( ROUND( AVERAGE( FILTER( 'Labse Top K=3 Chunk = 32'!F:F, TRIM('Labse Top K=3 Chunk = 32'!J:J)=""Comparative Synthesis"" ) ), 4), ""Data tidak ada"" ) "),0.6743) -> 0.6743 | G37: =IFERROR(__xludf.DUMMYFUNCTION("IFERROR( ROUND( AVERAGE( FILTER( 'Labse Top K=3 Chunk = 32'!G:G, TRIM('Labse Top K=3 Chunk = 32'!J:J)=""Comparative Synthesis"" ) ), 4), ""Data tidak ada"" ) "),0.575) -> 0.575 | H37: =IFERROR(__xludf.DUMMYFUNCTION("IFERROR( ROUND( AVERAGE( FILTER( 'Labse Top K=3 Chunk = 32'!H:H, TRIM('Labse Top K=3 Chunk = 32'!J:J)=""Comparative Synthesis"" ) ), 4), ""Data tidak ada"" ) "),0.4945) -> 0.4945
A38: LaBSE | B38: Evidence-based QA | C38: 32 | D38: 3 | E38: =IFERROR(__xludf.DUMMYFUNCTION("IFERROR( ROUND( AVERAGE( FILTER( 'Labse Top K=3 Chunk = 32'!E:E, TRIM('Labse Top K=3 Chunk = 32'!J:J)=""Evidence-based QA"" ) ), 4), ""Data tidak ada"" ) "),0.5962) -> 0.5962 | F38: =IFERROR(__xludf.DUMMYFUNCTION("IFERROR( ROUND( AVERAGE( FILTER( 'Labse Top K=3 Chunk = 32'!F:F, TRIM('Labse Top K=3 Chunk = 32'!J:J)=""Evidence-based QA"" ) ), 4), ""Data tidak ada"" ) "),0.4891) -> 0.4891 | G38: =IFERROR(__xludf.DUMMYFUNCTION("IFERROR( ROUND( AVERAGE( FILTER( 'Labse Top K=3 Chunk = 32'!G:G, TRIM('Labse Top K=3 Chunk = 32'!J:J)=""Evidence-based QA"" ) ), 4), ""Data tidak ada"" ) "),0.4625) -> 0.4625 | H38: =IFERROR(__xludf.DUMMYFUNCTION("IFERROR( ROUND( AVERAGE( FILTER( 'Labse Top K=3 Chunk = 32'!H:H, TRIM('Labse Top K=3 Chunk = 32'!J:J)=""Evidence-based QA"" ) ), 4), ""Data tidak ada"" ) "),0.6675) -> 0.6675
A39: LaBSE | B39: Trend Analysis | C39: 32 | D39: 5 | E39: =IFERROR(__xludf.DUMMYFUNCTION("IFERROR( ROUND( AVERAGE( FILTER( 'Labse Top K=5 Chunk = 32'!E:E, TRIM('Labse Top K=5 Chunk = 32'!J:J)=""Trend Analysis"" ) ), 4), ""Data tidak ada"" ) "),0.7202) -> 0.7202 | F39: =IFERROR(__xludf.DUMMYFUNCTION("IFERROR( ROUND( AVERAGE( FILTER( 'Labse Top K=5 Chunk = 32'!F:F, TRIM('Labse Top K=5 Chunk = 32'!J:J)=""Trend Analysis"" ) ), 4), ""Data tidak ada"" ) "),0.7294) -> 0.7294 | G39: =IFERROR(__xludf.DUMMYFUNCTION("IFERROR( ROUND( AVERAGE( FILTER( 'Labse Top K=5 Chunk = 32'!G:G, TRIM('Labse Top K=5 Chunk = 32'!J:J)=""Trend Analysis"" ) ), 4), ""Data tidak ada"" ) "),0.5473) -> 0.5473 | H39: =IFERROR(__xludf.DUMMYFUNCTION("IFERROR( ROUND( AVERAGE( FILTER( 'Labse Top K=5 Chunk = 32'!H:H, TRIM('Labse Top K=5 Chunk = 32'!J:J)=""Trend Analysis"" ) ), 4), ""Data tidak ada"" ) "),0.785) -> 0.785
A40: LaBSE | B40: Gap Detection | C40: 32 | D40: 5 | E40: =IFERROR(__xludf.DUMMYFUNCTION("IFERROR( ROUND( AVERAGE( FILTER( 'Labse Top K=5 Chunk = 32'!E:E, TRIM('Labse Top K=5 Chunk = 32'!J:J)=""Gap Detection"" ) ), 4), ""Data tidak ada"" ) "),0.6301) -> 0.6301 | F40: =IFERROR(__xludf.DUMMYFUNCTION("IFERROR( ROUND( AVERAGE( FILTER( 'Labse Top K=5 Chunk = 32'!F:F, TRIM('Labse Top K=5 Chunk = 32'!J:J)=""Gap Detection"" ) ), 4), ""Data tidak ada"" ) "),0.6617) -> 0.6617 | G40: =IFERROR(__xludf.DUMMYFUNCTION("IFERROR( ROUND( AVERAGE( FILTER( 'Labse Top K=5 Chunk = 32'!G:G, TRIM('Labse Top K=5 Chunk = 32'!J:J)=""Gap Detection"" ) ), 4), ""Data tidak ada"" ) "),0.7106) -> 0.7106 | H40: =IFERROR(__xludf.DUMMYFUNCTION("IFERROR( ROUND( AVERAGE( FILTER( 'Labse Top K=5 Chunk = 32'!H:H, TRIM('Labse Top K=5 Chunk = 32'!J:J)=""Gap Detection"" ) ), 4), ""Data tidak ada"" ) "),0.7442) -> 0.7442
A41: LaBSE | B41: Comparative Synthesis | C41: 32 | D41: 5 | E41: =IFERROR(__xludf.DUMMYFUNCTION("IFERROR( ROUND( AVERAGE( FILTER( 'Labse Top K=5 Chunk = 32'!E:E, TRIM('Labse Top K=5 Chunk = 32'!J:J)=""Comparative Synthesis"" ) ), 4), ""Data tidak ada"" ) "),0.5153) -> 0.5153 | F41: =IFERROR(__xludf.DUMMYFUNCTION("IFERROR( ROUND( AVERAGE( FILTER( 'Labse Top K=5 Chunk = 32'!F:F, TRIM('Labse Top K=5 Chunk = 32'!J:J)=""Comparative Synthesis"" ) ), 4), ""Data tidak ada"" ) "),0.8072) -> 0.8072 | G41: =IFERROR(__xludf.DUMMYFUNCTION("IFERROR( ROUND( AVERAGE( FILTER( 'Labse Top K=5 Chunk = 32'!G:G, TRIM('Labse Top K=5 Chunk = 32'!J:J)=""Comparative Synthesis"" ) ), 4), ""Data tidak ada"" ) "),0.644) -> 0.644 | H41: =IFERROR(__xludf.DUMMYFUNCTION("IFERROR( ROUND( AVERAGE( FILTER( 'Labse Top K=5 Chunk = 32'!H:H, TRIM('Labse Top K=5 Chunk = 32'!J:J)=""Comparative Synthesis"" ) ), 4), ""Data tidak ada"" ) "),0.596) -> 0.596
A42: LaBSE | B42: Evidence-based QA | C42: 32 | D42: 5 | E42: =IFERROR(__xludf.DUMMYFUNCTION("IFERROR( ROUND( AVERAGE( FILTER( 'Labse Top K=5 Chunk = 32'!E:E, TRIM('Labse Top K=5 Chunk = 32'!J:J)=""Evidence-based QA"" ) ), 4), ""Data tidak ada"" ) "),0.5844) -> 0.5844 | F42: =IFERROR(__xludf.DUMMYFUNCTION("IFERROR( ROUND( AVERAGE( FILTER( 'Labse Top K=5 Chunk = 32'!F:F, TRIM('Labse Top K=5 Chunk = 32'!J:J)=""Evidence-based QA"" ) ), 4), ""Data tidak ada"" ) "),0.6942) -> 0.6942 | G42: =IFERROR(__xludf.DUMMYFUNCTION("IFERROR( ROUND( AVERAGE( FILTER( 'Labse Top K=5 Chunk = 32'!G:G, TRIM('Labse Top K=5 Chunk = 32'!J:J)=""Evidence-based QA"" ) ), 4), ""Data tidak ada"" ) "),0.4773) -> 0.4773 | H42: =IFERROR(__xludf.DUMMYFUNCTION("IFERROR( ROUND( AVERAGE( FILTER( 'Labse Top K=3 Chunk = 64'!H:H, TRIM('Labse Top K=3 Chunk = 64'!J:J)=""Evidence-based QA"" ) ), 4), ""Data tidak ada"" ) "),0.7034) -> 0.7034
A43: LaBSE | B43: Trend Analysis | C43: 64 | D43: 3 | E43: =IFERROR(__xludf.DUMMYFUNCTION("IFERROR( ROUND( AVERAGE( FILTER( 'Labse Top K=3 Chunk = 64'!E:E, TRIM('Labse Top K=3 Chunk = 64'!J:J)=""Trend Analysis"" ) ), 4), ""Data tidak ada"" ) "),0.5604) -> 0.5604 | F43: =IFERROR(__xludf.DUMMYFUNCTION("IFERROR( ROUND( AVERAGE( FILTER( 'Labse Top K=3 Chunk = 64'!F:F, TRIM('Labse Top K=3 Chunk = 64'!J:J)=""Trend Analysis"" ) ), 4), ""Data tidak ada"" ) "),0.6707) -> 0.6707 | G43: =IFERROR(__xludf.DUMMYFUNCTION("IFERROR( ROUND( AVERAGE( FILTER( 'Labse Top K=3 Chunk = 64'!G:G, TRIM('Labse Top K=3 Chunk = 64'!J:J)=""Trend Analysis"" ) ), 4), ""Data tidak ada"" ) "),0.4957) -> 0.4957 | H43: =IFERROR(__xludf.DUMMYFUNCTION("IFERROR( ROUND( AVERAGE( FILTER( 'Labse Top K=3 Chunk = 64'!H:H, TRIM('Labse Top K=3 Chunk = 64'!J:J)=""Trend Analysis"" ) ), 4), ""Data tidak ada"" ) "),0.7846) -> 0.7846
A44: LaBSE | B44: Gap Detection | C44: 64 | D44: 3 | E44: =IFERROR(__xludf.DUMMYFUNCTION("IFERROR( ROUND( AVERAGE( FILTER( 'Labse Top K=3 Chunk = 64'!E:E, TRIM('Labse Top K=3 Chunk = 64'!J:J)=""Gap Detection"" ) ), 4), ""Data tidak ada"" ) "),0.6381) -> 0.6381 | F44: =IFERROR(__xludf.DUMMYFUNCTION("IFERROR( ROUND( AVERAGE( FILTER( 'Labse Top K=3 Chunk = 64'!F:F, TRIM('Labse Top K=3 Chunk = 64'!J:J)=""Gap Detection"" ) ), 4), ""Data tidak ada"" ) "),0.5786) -> 0.5786 | G44: =IFERROR(__xludf.DUMMYFUNCTION("IFERROR( ROUND( AVERAGE( FILTER( 'Labse Top K=3 Chunk = 64'!G:G, TRIM('Labse Top K=3 Chunk = 64'!J:J)=""Gap Detection"" ) ), 4), ""Data tidak ada"" ) "),0.6916) -> 0.6916 | H44: =IFERROR(__xludf.DUMMYFUNCTION("IFERROR( ROUND( AVERAGE( FILTER( 'Labse Top K=3 Chunk = 64'!H:H, TRIM('Labse Top K=3 Chunk = 64'!J:J)=""Gap Detection"" ) ), 4), ""Data tidak ada"" ) "),0.6686) -> 0.6686
A45: LaBSE | B45: Comparative Synthesis | C45: 64 | D45: 3 | E45: =IFERROR(__xludf.DUMMYFUNCTION("IFERROR( ROUND( AVERAGE( FILTER( 'Labse Top K=3 Chunk = 64'!E:E, TRIM('Labse Top K=3 Chunk = 64'!J:J)=""Comparative Synthesis"" ) ), 4), ""Data tidak ada"" ) "),0.6239) -> 0.6239 | F45: =IFERROR(__xludf.DUMMYFUNCTION("IFERROR( ROUND( AVERAGE( FILTER( 'Labse Top K=3 Chunk = 64'!F:F, TRIM('Labse Top K=3 Chunk = 64'!J:J)=""Comparative Synthesis"" ) ), 4), ""Data tidak ada"" ) "),0.7929) -> 0.7929 | G45: =IFERROR(__xludf.DUMMYFUNCTION("IFERROR( ROUND( AVERAGE( FILTER( 'Labse Top K=3 Chunk = 64'!G:G, TRIM('Labse Top K=3 Chunk = 64'!J:J)=""Comparative Synthesis"" ) ), 4), ""Data tidak ada"" ) "),0.6583) -> 0.6583 | H45: =IFERROR(__xludf.DUMMYFUNCTION("IFERROR( ROUND( AVERAGE( FILTER( 'Labse Top K=5 Chunk = 64'!H:H, TRIM('Labse Top K=5 Chunk = 64'!J:J)=""Comparative Synthesis"" ) ), 4), ""Data tidak ada"" ) "),0.5604) -> 0.5604
A46: LaBSE | B46: Evidence-based QA | C46: 64 | D46: 3 | E46: =IFERROR(__xludf.DUMMYFUNCTION("IFERROR( ROUND( AVERAGE( FILTER( 'Labse Top K=3 Chunk = 64'!E:E, TRIM('Labse Top K=3 Chunk = 64'!J:J)=""Evidence-based QA"" ) ), 4), ""Data tidak ada"" ) "),0.5819) -> 0.5819 | F46: =IFERROR(__xludf.DUMMYFUNCTION("IFERROR( ROUND( AVERAGE( FILTER( 'Labse Top K=3 Chunk = 64'!F:F, TRIM('Labse Top K=3 Chunk = 64'!J:J)=""Evidence-based QA"" ) ), 4), ""Data tidak ada"" ) "),0.4309) -> 0.4309 | G46: =IFERROR(__xludf.DUMMYFUNCTION("IFERROR( ROUND( AVERAGE( FILTER( 'Labse Top K=3 Chunk = 64'!G:G, TRIM('Labse Top K=3 Chunk = 64'!J:J)=""Evidence-based QA"" ) ), 4), ""Data tidak ada"" ) "),0.4583) -> 0.4583 | H46: =IFERROR(__xludf.DUMMYFUNCTION("IFERROR( ROUND( AVERAGE( FILTER( 'Labse Top K=3 Chunk = 64'!H:H, TRIM('Labse Top K=3 Chunk = 64'!J:J)=""Evidence-based QA"" ) ), 4), ""Data tidak ada"" ) "),0.7034) -> 0.7034
A47: LaBSE | B47: Trend Analysis | C47: 64 | D47: 5 | E47: =IFERROR(__xludf.DUMMYFUNCTION("IFERROR( ROUND( AVERAGE( FILTER( 'Labse Top K=5 Chunk = 64'!E:E, TRIM('Labse Top K=5 Chunk = 64'!J:J)=""Trend Analysis"" ) ), 4), ""Data tidak ada"" ) "),0.6096) -> 0.6096 | F47: =IFERROR(__xludf.DUMMYFUNCTION("IFERROR( ROUND( AVERAGE( FILTER( 'Labse Top K=5 Chunk = 64'!F:F, TRIM('Labse Top K=5 Chunk = 64'!J:J)=""Trend Analysis"" ) ), 4), ""Data tidak ada"" ) "),0.7837) -> 0.7837 | G47: =IFERROR(__xludf.DUMMYFUNCTION("IFERROR( ROUND( AVERAGE( FILTER( 'Labse Top K=5 Chunk = 64'!G:G, TRIM('Labse Top K=5 Chunk = 64'!J:J)=""Trend Analysis"" ) ), 4), ""Data tidak ada"" ) "),0.6506) -> 0.6506 | H47: =IFERROR(__xludf.DUMMYFUNCTION("IFERROR( ROUND( AVERAGE( FILTER( 'Labse Top K=5 Chunk = 64'!H:H, TRIM('Labse Top K=5 Chunk = 64'!J:J)=""Trend Analysis"" ) ), 4), ""Data tidak ada"" ) "),0.7875) -> 0.7875
A48: LaBSE | B48: Gap Detection | C48: 64 | D48: 5 | E48: =IFERROR(__xludf.DUMMYFUNCTION("IFERROR( ROUND( AVERAGE( FILTER( 'Labse Top K=5 Chunk = 64'!E:E, TRIM('Labse Top K=5 Chunk = 64'!J:J)=""Gap Detection"" ) ), 4), ""Data tidak ada"" ) "),0.5862) -> 0.5862 | F48: =IFERROR(__xludf.DUMMYFUNCTION("IFERROR( ROUND( AVERAGE( FILTER( 'Labse Top K=5 Chunk = 64'!F:F, TRIM('Labse Top K=5 Chunk = 64'!J:J)=""Gap Detection"" ) ), 4), ""Data tidak ada"" ) "),0.641) -> 0.641 | G48: =IFERROR(__xludf.DUMMYFUNCTION("IFERROR( ROUND( AVERAGE( FILTER( 'Labse Top K=5 Chunk = 64'!G:G, TRIM('Labse Top K=5 Chunk = 64'!J:J)=""Gap Detection"" ) ), 4), ""Data tidak ada"" ) "),0.7229) -> 0.7229 | H48: =IFERROR(__xludf.DUMMYFUNCTION("IFERROR( ROUND( AVERAGE( FILTER( 'Labse Top K=5 Chunk = 64'!H:H, TRIM('Labse Top K=5 Chunk = 64'!J:J)=""Gap Detection"" ) ), 4), ""Data tidak ada"" ) "),0.778) -> 0.778
A49: LaBSE | B49: Comparative Synthesis | C49: 64 | D49: 5 | E49: =IFERROR(__xludf.DUMMYFUNCTION("IFERROR( ROUND( AVERAGE( FILTER( 'Labse Top K=5 Chunk = 64'!E:E, TRIM('Labse Top K=5 Chunk = 64'!J:J)=""Comparative Synthesis"" ) ), 4), ""Data tidak ada"" ) "),0.6026) -> 0.6026 | F49: =IFERROR(__xludf.DUMMYFUNCTION("IFERROR( ROUND( AVERAGE( FILTER( 'Labse Top K=5 Chunk = 64'!F:F, TRIM('Labse Top K=5 Chunk = 64'!J:J)=""Comparative Synthesis"" ) ), 4), ""Data tidak ada"" ) "),0.6917) -> 0.6917 | G49: =IFERROR(__xludf.DUMMYFUNCTION("IFERROR( ROUND( AVERAGE( FILTER( 'Labse Top K=5 Chunk = 64'!G:G, TRIM('Labse Top K=5 Chunk = 64'!J:J)=""Comparative Synthesis"" ) ), 4), ""Data tidak ada"" ) "),0.6328) -> 0.6328 | H49: =IFERROR(__xludf.DUMMYFUNCTION("IFERROR( ROUND( AVERAGE( FILTER( 'Labse Top K=5 Chunk = 64'!H:H, TRIM('Labse Top K=5 Chunk = 64'!J:J)=""Comparative Synthesis"" ) ), 4), ""Data tidak ada"" ) "),0.5604) -> 0.5604
A50: LaBSE | B50: Evidence-based QA | C50: 64 | D50: 5 | E50: =IFERROR(__xludf.DUMMYFUNCTION("IFERROR( ROUND( AVERAGE( FILTER( 'Labse Top K=5 Chunk = 64'!E:E, TRIM('Labse Top K=5 Chunk = 64'!J:J)=""Evidence-based QA"" ) ), 4), ""Data tidak ada"" ) "),0.6823) -> 0.6823 | F50: =IFERROR(__xludf.DUMMYFUNCTION("IFERROR( ROUND( AVERAGE( FILTER( 'Labse Top K=5 Chunk = 64'!F:F, TRIM('Labse Top K=5 Chunk = 64'!J:J)=""Evidence-based QA"" ) ), 4), ""Data tidak ada"" ) "),0.499) -> 0.499 | G50: =IFERROR(__xludf.DUMMYFUNCTION("IFERROR( ROUND( AVERAGE( FILTER( 'Labse Top K=5 Chunk = 64'!G:G, TRIM('Labse Top K=5 Chunk = 64'!J:J)=""Evidence-based QA"" ) ), 4), ""Data tidak ada"" ) "),0.4427) -> 0.4427 | H50: =IFERROR(__xludf.DUMMYFUNCTION("IFERROR( ROUND( AVERAGE( FILTER( 'Labse Top K=5 Chunk = 64'!H:H, TRIM('Labse Top K=5 Chunk = 64'!J:J)=""Evidence-based QA"" ) ), 4), ""Data tidak ada"" ) "),0.7671) -> 0.7671
...

Sheet Rekap hasil seluruh pengujian s
A1: No | B1: Model | C1: Chunking | D1: Top K | E1: Question | F1: Answer | G1: Top_K_Sources | H1: Faithfulness | I1: Answer_Relevancy | J1: Context_Precision | K1: Context_Recall | L1: Image_Path
A2: {=SEQUENCE(640,1)} -> 1 | B2: LaBSE | C2: 32 | D2: 3 | E2: How has the application of AI in supply chain risk management evolved over time? | F2: Direct Summary: The application of AI in supply chain risk management has evolved over time, shifting from a focus on prediction performance to exploring its impact on service models and various segments of the supply chain. Initially, most works focused on prediction performance, but recent studies have expanded to include the investigation of AI's applicability in supply chain risk management. This evolution indicates a growing recognition of AI's potential in supply chain management. Detailed Synthesis: Initially, the application of AI in supply chain risk management focused on prediction performance, as seen in works such as Baryannis et al. (2019) [1]. However, recent studies have expanded to include the investigation of AI's applicability in supply chain risk management, indicating a growing recognition of AI's potential in supply chain management. Recent studies, such as Wang et al. (2025) [2], have explored the application of AI in supply chain management, focusing on its impact on service models at both the front and back ends of the supply chain. The evolution of AI's application in supply chain risk management is also reflected in its increasing adoption across various segments of the supply chain, as seen in the food industry, where AI is being applied in breeding, cultivation, production, processing, safety testing, and more, as discussed in Ding et al. (2025) [3]. Analysis grounded in primary sources: [Baryannis et al., 2019; Wang et al., 2025; Ding et al., 2025]. | G2: Rank #1 Potongan Chunk: same time the resurgence of artificial intelligence ai has led to the investigation of machine learning techniques and their applicability in supply chain risk management however most works focus on prediction performance... Title: predicting supply chain risks using machine learning the tradeoff between performance and interpretability Authors: Baryannis, G.; Dani, S.; Antoniou, G. Score: 0.5620 ----------------- Rank #2 Potongan Chunk: this paper explores the application of artificial intelligence ai in supply chain management focusing on its impact on service models at both the front and back ends of the supply chain sc... Title: is it necessary for the supply chain to implement artificial intelligencedriven sales services at both the frontend and backend stages Authors: Wang, Y.; Gao, J.; Cheng, T.C.E.; Jin, M.; Yue, X.; Wang, H. Score: 0.5546 ----------------- Rank #3 Potongan Chunk: with the rapid development of artificial intelligence ai technology its application in the food industry has become increasingly widespread covering various segments from breeding and cultivation production and processing safety testing and... Title: applications and prospects of artificial intelligence in the food industry Authors: Ding, H.; Song, X.; Dong, G.; Zhang, X.; Wang, C.; Cui, X.; Hou, H.; Huang, H.; Xu, S.; Han, Y.; Yang, Y. Score: 0.5279 | H2: 1 | I2: 0.901 | J2: 1 | K2: 0.875 | L2: =IMAGE("https://drive.google.com/uc?export=view&id=1yWqfLrwrmcdiwdqVorVHl9lGOMhO-QEg")
A3: 2 | B3: LaBSE | C3: 32 | D3: 3 | E3: What were the dominant AI techniques used in early research on supply chain resilience? | F3: Direct Summary: The dominant AI techniques used in early research on supply chain resilience were primarily focused on prediction performance, with most works utilizing machine learning techniques. Detailed Synthesis: According to Doc [3], machine learning techniques were the primary focus in early research on supply chain risk management, with a focus on prediction performance [3]. However, as noted in Doc [1], the majority of AI approaches explored in supply chain research afford little to no explainability, which is a significant limitation [1]. Analysis grounded in primary sources: [Baryannis, G.; Dani, S.; Antoniou, G., 2019; Kosasih, E.E.; Papadakis, E.; Baryannis, G.; Brintrup, A., 2024]. | G3: Rank #1 Potongan Chunk: artificial intelligence ai has emerged as a complementary technology in supply chain research however the majority of ai approaches explored in this context afford little to no explainability which is a significant... Title: a review of explainable artificial intelligence in supply chain management using neurosymbolic approaches Authors: Kosasih, E.E.; Papadakis, E.; Baryannis, G.; Brintrup, A. Score: 0.5819 ----------------- Rank #2 Potongan Chunk: study aims primarily to provide insight into the artificial intelligence ai tools used in supply chain management processes using the supply chain operations reference scor approach it also seeks to examine the... Title: exploring the power of artificial intelligence in supply chain management a literature review on the artificial intelligence applications and tools used in supply chains and their distribution according to the scor method Authors: Harrir, M.M.; Triqui, L. Score: 0.5498 ----------------- Rank #3 Potongan Chunk: same time the resurgence of artificial intelligence ai has led to the investigation of machine learning techniques and their applicability in supply chain risk management however most works focus on prediction performance... Title: predicting supply chain risks using machine learning the tradeoff between performance and interpretability Authors: Baryannis, G.; Dani, S.; Antoniou, G. Score: 0.5465 | H3: 0.429 | I3: 1 | J3: 0.333 | K3: 1 | L3: =IMAGE("https://drive.google.com/uc?export=view&id=1FxO3OeVVwVfdbWaVF-TiLUcIeXutQ-6f")
A4: 3 | B4: LaBSE | C4: 32 | D4: 3 | E4: How did machine learning adoption change SCRM research after 2015? | F4: Direct Summary: Machine learning adoption significantly impacted SCRM research after 2015, as evident from the increasing number of studies exploring its applications in SCM. This shift is attributed to the growing interest in leveraging AI and ML for more efficient and sustainable supply chain management. Detailed Synthesis: According to Doc [3], the rapid growth of interest in deep learning, a class of machine learning algorithms, in SCM has led to an urgent need for an updated systematic review on research development [1]. As stated in Doc [1], this study examined articles published since 2015 to understand the current status, future possibilities, and capabilities of ML in supporting environmentally friendly development [2]. Similarly, Doc [2] highlights the importance of AI and ML in effectively adopting and implementing the circular economy in real-world practices [3]. Analysis grounded in primary sources: Hosseinnia Shavaki, F.H.; Ebrahimi Ghahnavieh, A. (2023), Noman, A.A.; Akter, U.H.; Pranto, T.H.; Haque, A.K.M.B. (2022), Claude, B.M.J.; Sibali, L.L. (2024). | G4: Rank #1 Potongan Chunk: use machine learning ml a new technique approach this study examined articles published since 2015 to understand better the current status future possibilities and capabilities of ml in supporting environmentally friendly development... Title: application of machine learning for environmentally friendly advancement exploring biomassderived materials in wastewater treatment and agricultural sector a review Authors: Claude, B.M.J.; Sibali, L.L. Score: 0.4867 ----------------- Rank #2 Potongan Chunk: later on by reusing recycling and remanufacturing innovative technologies like artificial intelligence ai and machine learningml provide vital assistance in effectively adopting and implementing ce in realworld practices this study explores the... Title: machine learning and artificial intelligence in circular economy a bibliometric analysis and systematic literature review Authors: Noman, A.A.; Akter, U.H.; Pranto, T.H.; Haque, A.K.M.B. Score: 0.4789 ----------------- Rank #3 Potongan Chunk: rapidly growing interest in the application of deep learning a class of machine learning algorithms in scm has urged the need for an uptodate systematic review on the research development the main... Title: applications of deep learning into supply chain management a systematic literature review and a framework for future research Authors: Hosseinnia Shavaki, F.H.; Ebrahimi Ghahnavieh, A. Score: 0.4678 | H4: 1 | I4: 0.827 | J4: 1 | K4: 0.333 | L4: =IMAGE("https://drive.google.com/uc?export=view&id=1dV58gtSqEiTa5kdZ6WMlUDwpnp4_jjSm")
A5: 4 | B5: LaBSE | C5: 32 | D5: 3 | E5: What role did predictive analytics play in early supply chain risk mitigation studies? | F5: Direct Summary: Predictive analytics played a crucial role in early supply chain risk mitigation studies, particularly in identifying and mitigating risks in retail supply chains and agricultural supply chains. This was achieved through the application of big data analytics and machine learning techniques. Detailed Synthesis: Predictive analytics was used to identify and mitigate risks in retail supply chains, as seen in the study by Xue et al. (2019) [1], which employed a difference measure method based on moment generating function and fuzzy data stream clustering. Big data analytics was applied to mitigate supply chain social risk in manufacturing supply chains, as demonstrated by Venkatesh et al. (2017) [2], who explored the application of big data analytics in mitigating supply chain social risk. Predictive analytics was also used in agricultural supply chains, as seen in the study by Han et al. (2024) [3], which employed big data-driven risk decision-making and safety management strategies. Analysis grounded in primary sources: [Xue et al., 2019; Venkatesh et al., 2017; Han et al., 2024]. | G5: Rank #1 Potongan Chunk: the research of the difference measure method for risk probability distribution plays a key role in the early warning decisionmaking management of retail supply chain unconventional emergency however the common difference measure... Title: difference measure method of risk probability distribution based on moment generating function and fuzzy data stream clustering Authors: Xue, H.; Yuan, Y.; Jiang, C.; Cai, B.-Y. Score: 0.5337 ----------------- Rank #2 Potongan Chunk: importance to the sustainable enterprise the aim of this research is to explore the application of big data analytics in mitigating supply chain social risk and to demonstrate how such mitigation can... Title: mitigating supply chain risk via sustainability using big data analytics evidence from the manufacturing supply chain Authors: Venkatesh, V.; Delgado, C.; Hazen, B.T.; Patel, P. Score: 0.4937 ----------------- Rank #3 Potongan Chunk: adopt effective risk management strategies is paramount contemporary studies have explored the utilization of big data in decisionmaking processes specific to agricultural supply chain risks predominantly concentrating on preliminary risk prediction and... Title: big datadriven risk decisionmaking and safety management in agricultural supply chains Authors: Han, G.; Pan, X.; Zhang, X. Score: 0.4916 | H5: 0.571 | I5: 1 | J5: 1 | K5: 1 | L5: =IMAGE("https://drive.google.com/uc?export=view&id=1A27oO-piM3pvWsnAMdr8bRcHquE5OX4D")
A6: 5 | B6: LaBSE | C6: 32 | D6: 3 | E6: How has deep learning influenced recent supply chain resilience models? | F6: Direct Summary: Deep learning has significantly influenced recent supply chain resilience models by enabling advanced techniques such as predictive analytics and machine learning algorithms to improve efficiency and visibility in supply chain management. Detailed Synthesis: Deep learning has been used to develop predictive models that can forecast demand and supply, enabling supply chain managers to make informed decisions and improve resilience [1]. The use of deep Q-learning has been shown to improve supply chain management procedures by enabling data-driven decision making and optimizing supply chain operations [2]. Advanced deep learning techniques have also been used to develop optimized provenance systems that can improve visibility and transparency in the supply chain, reducing the risk of disruptions and improving resilience [3]. Analysis grounded in primary sources: [Ghodake et al., 2024; Abekoon et al., 2024; Khan et al., 2020]. | G6: Rank #1 Potongan Chunk: notable gains above baseline methods highlighting the importance of dql in supply chain management this study demonstrates how deep qlearning has the ability to completely change supply chain management procedures in todays... Title: enhancing supply chain management efficiency a datadriven approach using predictive analytics and machine learning algorithms Authors: Ghodake, S.P.; Malkar, V.R.; Santosh, K.; Jabasheela, L.; Abdufattokhov, S.; Gopi, A. Score: 0.5184 ----------------- Rank #2 Potongan Chunk: this study reviews recent advancements in food science and technology analyzing their impact on the development of intelligent food packaging within the complex food supply chain modern food technology has brought about... Title: a comprehensive review to evaluate the synergy of intelligent food packaging with modern food technology and artificial intelligence field Authors: Abekoon, T.; Buthpitiya, B.L.S.K.; Sajindra, H.; Samarakoon, E.R.J.; Jayakody, J.A.D.C.A.; Kantamaneni, K.; Rathnayake, U. Score: 0.4993 ----------------- Rank #3 Potongan Chunk: by advanced deep learning adl techniques the importance of such innovations from the viewpoint of supply chain management is significant in different processes such as for broadened visibility provenance digitalization disintermediation and... Title: iotblockchain enabled optimized provenance system for food industry 40 using advanced deep learning Authors: Khan, P.W.; Byun, Y.-C.; Park, N. Score: 0.4927 | H6: 0.667 | I6: 0.734 | J6: 0.833 | K6: 0.6 | L6: =IMAGE("https://drive.google.com/uc?export=view&id=1o4D6HkiN88UnJ0EddFdQZvlMOl6o87ym")
A7: 6 | B7: LaBSE | C7: 32 | D7: 3 | E7: What major paradigm shifts occurred after COVID-19 in AI-based supply chain research? | F7: Direct Summary: Major paradigm shifts occurred after COVID-19 in AI-based supply chain research, including the increased focus on supply chain resilience, risk-aware procurement optimization, and the adoption of big data-driven innovation. Detailed Synthesis: The COVID-19 pandemic highlighted the importance of supply chain resilience, leading to a shift in research focus towards developing risk-aware procurement optimization models, as seen in [3] by Chase et al. (2025). The pandemic also accelerated the adoption of big data-driven innovation in supply chain management, with studies exploring its potential to improve SCM processes, as discussed in [1] by Chatterjee et al. (2022). Furthermore, the pandemic demonstrated the value of AI and big data in enabling businesses to respond to crises and turn them into opportunities, as highlighted in [2] by Chen and Biswas (2021). Analysis grounded in primary sources: [Chatterjee et al., 2022; Chen & Biswas, 2021; Chase et al., 2025]. | G7: Rank #1 Potongan Chunk: literature has prescribed many treatments on how smes could survive in post covid19 situation but studies did not analyse how big data driven innovation could improve supply chain management scm process in... Title: big data driven innovation for sustaining sme supply chain operation in post covid19 scenario moderating role of sme technology leadership Authors: Chatterjee, S.; Chaudhuri, R.; Hussain Shah, M.; Maheshwari, P. Score: 0.5467 ----------------- Rank #2 Potongan Chunk: ai and big data for their business operations during the covid19 pandemic the outcomes of this study provide valuable insights into contemporary social science research and business management with ai and big... Title: turning crisis into opportunities how a firm can enrich its business operations using artificial intelligence and big data during covid19 Authors: Chen, Y.; Biswas, M.I. Score: 0.5464 ----------------- Rank #3 Potongan Chunk: supply chain resilience has been a topic of active research in the operations research and ai communities for several years but the covid19 pandemic threw the frailties of global supply chains into... Title: multiperiod riskaware procurement optimization under covid19 disruption Authors: Chase, J.; Lau, H.C.; Yang, J.; Liu, L. Score: 0.5464 | H7: 1 | I7: 1 | J7: 0.583 | K7: 1 | L7: =IMAGE("https://drive.google.com/uc?export=view&id=1xIBTZB3ErCMFr52F6orM-oFUqWVPaGaS")
A8: 7 | B8: LaBSE | C8: 32 | D8: 3 | E8: How did the focus move from reactive to proactive risk management? | F8: Direct Summary: The focus moved from reactive to proactive risk management as a result of advancements in technology and data-driven approaches, enabling supply chain professionals to anticipate and mitigate potential risks before they occur. Detailed Synthesis: According to Doc [3], the integration of data-driven and artificial intelligence frameworks has enabled the development of digital twins in distribution systems, allowing for proactive design and management of future demand risks [3]. Doc [1] highlights the importance of explainability in supply chain operational risk management, emphasizing the need for proactive risk management strategies rather than just reactive measures [1]. Doc [2] discusses the paradigm shift from reactive to predictive aflatoxin management, which enhances food safety and security, and public health worldwide [2]. Analysis grounded in primary sources: Nimmy, S.F. et al. (2022), Yohannis, E. et al. (2025), Ziari, M. et al. (2025). | G8: Rank #1 Potongan Chunk: risk management action rather than just what they should do to manage the operational risks 2021 elsevier bv... Title: explainability in supply chain operational risk management a systematic literature review Authors: Nimmy, S.F.; Hussain, O.K.; Chakrabortty, R.K.; Hussain, F.K.; Saberi, M. Score: 0.4136 ----------------- Rank #2 Potongan Chunk: a paradigm shift from reactive to predictive af management enhancing food safety and security and public health worldwide 2025 the authors... Title: omics approaches to aflatoxin contaminations in the agrifood supply chain a comprehensive review of current advances challenges and future potential Authors: Yohannis, E.; Teka, T.A.; Urugo, M.M.; Tola, Y.B.; Getachew, P. Score: 0.3925 ----------------- Rank #3 Potongan Chunk: scenarios 1 proactive design for managing future demand risks and 2 reactive design for managing realtime demand risks this research aims to provide a more comprehensive study compared to previous investigations by... Title: integrated datadriven and artificial intelligence framework to develop digital twins in distribution system of supply chains a real industrial case Authors: Ziari, M.; Taleizadeh, A.A. Score: 0.3725 | H8: 0 | I8: 0.81 | J8: 0 | K8: 0.2 | L8: =IMAGE("https://drive.google.com/uc?export=view&id=19w73J71Q6HnNGTwLM0fZ8hw84ev8h03Y")
A9: 8 | B9: LaBSE | C9: 32 | D9: 3 | E9: What trends show the integration of real-time data and AI in SCRM? | F9: Direct Summary: The integration of real-time data and AI in Supply Chain Risk Management (SCRM) is transforming the industry by enabling smarter, faster, and more adaptable operations. Key applications include predictive analytics for demand forecasting, real-time inventory tracking, and end-to-end visibility between globally distributed companies. Detailed Synthesis: The use of real-time data and AI in SCRM enables companies to make data-driven decisions, improve forecasting accuracy, and reduce inventory costs [1]. Real-time inventory tracking and end-to-end visibility between globally distributed companies improve supply chain resilience and reduce the risk of stockouts and overstocking [2]. The integration of AI in SCRM also enables predictive analytics, which can help companies anticipate and respond to disruptions in the supply chain [3]. Analysis grounded in primary sources: [Pessot, Zangiacomi, Fornasiero, 2024; Akter, Khan, Ullah, Mozumder, Choi, Kim, 2025; Price, Vavra, 2021]. References: [1] Pessot, E.; Zangiacomi, A.; Fornasiero, R. (2024). Unboxing the Hyperconnected Supply Chain: A Case Study in the Furniture Industry. [2] Akter, S.S.; Khan, M.O.; Ullah, K.; Mozumder, M.A.I.; Choi, Y.; Kim, H.-C. (2025). Integration of Advanced Artificial Intelligence in Supply Chain Management: Its Challenges and Opportunities. [3] Price, C.; Vavra, C. (2021). How to Improve Cybersecurity. | G9: Rank #1 Potongan Chunk: reality and artificial intelligence we analyze how sc actors combine these technologies to develop their sc processes and routines in terms of realtime data exchange and endtoend visibility between globally distributed companies... Title: unboxing the hyperconnected supply chain a case study in the furniture industry Authors: Pessot, E.; Zangiacomi, A.; Fornasiero, R. Score: 0.5561 ----------------- Rank #2 Potongan Chunk: integrating artificial intelligence ai into supply chain management scm is transforming the industry by enabling smarter faster and more adaptable operations key applications include predictive analytics for demand forecasting realtime inventory tracking... Title: integration of advanced artificial intelligence in supply chain management its challenges and opportunities Authors: Akter, S.S.; Khan, M.O.; Ullah, K.; Mozumder, M.A.I.; Choi, Y.; Kim, H.-C. Score: 0.5323 ----------------- Rank #3 Potongan Chunk: the digitalization revolution is integrating production with business processes and introducing artificial intelligence ai cloud computing and augmented reality ar into the workplace with realtime data collected across the business and supply... Title: how to improve cybersecurity Authors: Price, C.; Vavra, C. Score: 0.5180 | H9: 0.5 | I9: 0.821 | J9: 1 | K9: 0.333 | L9: =IMAGE("https://drive.google.com/uc?export=view&id=1LphF5CdNh_uDjN3IlHgSPN3v3EAGpgH6")
A10: 9 | B10: LaBSE | C10: 32 | D10: 3 | E10: How has the use of simulation-based AI models evolved? | F10: Direct Summary: The use of simulation-based AI models has evolved through advancements in artificial intelligence technologies, enabling the development and implementation of digital food systems and risk management strategies in various settings. Detailed Synthesis: The application of simulation-based AI models has been explored in various fields, including food safety and risk management, as evident in the works of Qian et al. (2023) and Kamakela et al. (2023) [1]. Machine learning, a branch of AI, has been used to develop mathematical models and predictive analytics for risk management, as discussed in Kamakela et al. (2023) [2]. Evolutionary machine learning, a subfield of machine learning, has also been explored in the context of AI, as seen in Al-Sahaf et al. (2019) [3]. Analysis grounded in primary sources: Qian, C.; Murphy, S.I.; Orsi, R.H.; Wiedmann, M. (2023), Kamakela, J.S.; Callychurn, D.; Hurreeram, D. (2023), Al-Sahaf, H.; Bi, Y.; Chen, Q.; Lensen, A.; Mei, Y.; Sun, Y.; Tran, B.; Xue, B.; Zhang, M. (2019). | G10: Rank #1 Potongan Chunk: with advances in artificial intelligence ai technologies the development and implementation of digital food systems are becoming increasingly possible there is tremendous interest in using different ai applications such as machine learning... Title: how can ai help improve food safety Authors: Qian, C.; Murphy, S.I.; Orsi, R.H.; Wiedmann, M. Score: 0.5446 ----------------- Rank #2 Potongan Chunk: the application of digital technologies in various settings using mathematical models machine learning a module under artificial intelligence ai received more attention however this study brings a new perspective by assessing ways... Title: assessing digital technology and analytics for risk management focus on fast moving consumer goods fmcg manufacturing firms in mauritius Authors: Kamakela, J.S.; Callychurn, D.; Hurreeram, D. Score: 0.5426 ----------------- Rank #3 Potongan Chunk: artificial intelligence ai emphasises the creation of intelligent machinessystems that function like humans ai has been applied to many realworld applications machine learning is a branch of ai based on the idea... Title: a survey on evolutionary machine learning Authors: Al-Sahaf, H.; Bi, Y.; Chen, Q.; Lensen, A.; Mei, Y.; Sun, Y.; Tran, B.; Xue, B.; Zhang, M. Score: 0.5150 | H10: 0.6 | I10: 0.523 | J10: 0.583 | K10: 0 | L10: =IMAGE("https://drive.google.com/uc?export=view&id=1k5RfntDpLiJXy1b_yK39qUp9v3t8FKo5")
A11: 10 | B11: LaBSE | C11: 32 | D11: 3 | E11: What changes occurred in the objectives of AI models for supply chain resilience? | F11: Direct Summary: The objectives of AI models for supply chain resilience have shifted towards enhancing supply chain resilience in manufacturing firms, particularly in strengthening supply chain resilience to survive in turbulent business environments. Detailed Synthesis: According to Doc [3], manufacturing firms must strengthen their supply chain resilience to survive in turbulent business environments, indicating a shift in the objectives of AI models from general supply chain management to resilience enhancement [3]. Doc [3] further explores how AI can be leveraged to enhance supply chain resilience, suggesting a change in the objectives of AI models from prediction and optimization to resilience and adaptability [3]. Analysis grounded in primary sources: Yue, X.; Kang, M.; Zhang, Y. (2025) and Ablegue, A.G.M.-D.; Zhang, M.; Guo, Q.; Rui, L. (2025). | G11: Rank #1 Potongan Chunk: discusses ai model validation frameworks essential for ensuring reliability and robustness of predictions in realworld food industry applications the integration of ai technologies with blockchain systems is further explored as a pathway... Title: monitoring and shelf life extension of food products based on machine learning and deep learning progress and potential applications Authors: Ablegue, A.G.M.-D.; Zhang, M.; Guo, Q.; Rui, L. Score: 0.4928 ----------------- Rank #2 Potongan Chunk: their key insights and contributions our findings demonstrate that ai has diverse applications in different aspects of the fashion industry enhancing sustainability efforts in supply chain management creative design sales and promotion... Title: artificial intelligence and sustainability in the fashion industry a review from 2010 to 2022 Authors: Ramos, L.; Rivas, F.; Pérez, A.G.; Casas, E. Score: 0.4898 ----------------- Rank #3 Potongan Chunk: purpose manufacturing firms must strengthen their supply chain resilience to survive in turbulent business environments this study explores how artificial intelligence ai can be leveraged to enhance supply chain resilience designmethodologyapproach drawing... Title: the impact of artificial intelligence usage on supply chain resilience in manufacturing firms a moderated mediation model Authors: Yue, X.; Kang, M.; Zhang, Y. Score: 0.4852 | H11: 0.286 | I11: 0.849 | J11: 0.333 | K11: 0.75 | L11: =IMAGE("https://drive.google.com/uc?export=view&id=16_CTN-aJL1gxlASC-0unn2FOlybBzKC-")
A12: 11 | B12: LaBSE | C12: 32 | D12: 3 | E12: How has explainable AI emerged in SCRM research? | F12: Direct Summary: Explainable AI (XAI) has emerged in Supply Chain Risk Management (SCRM) research through the development of typologies and research agendas, aiming to better align AI deployment in SCRM. This has been facilitated by the integration of AI applications in SCRM functional areas, as observed in recent literature. The emergence of XAI in SCRM research is expected to enhance the understanding of AI deployment in SCRM. Detailed Synthesis: XAI has emerged in SCRM research through the development of typologies and research agendas, as presented in Mugurusi and Oluka (2021) [1]. This aims to better align AI deployment in SCRM and enhance the understanding of AI applications in SCRM functional areas. The integration of AI applications in SCRM functional areas has gained much traction in recent literature, as observed in Prikshat et al. (2023) [2]. This has facilitated the emergence of XAI in SCRM research. Analysis grounded in primary sources: Mugurusi, G.; Oluka, P.N. (2021), Prikshat, V.; Islam, M.; Patel, P.; Malik, A.; Budhwar, P.; Gupta, S. (2023). | G12: Rank #1 Potongan Chunk: approaches and the emergence of artificial intelligence ai applications through an extensive database search relevant articles on cscrm were identified for analysis the review reveals that while traditional techniques such as surveys... Title: construction supply chain risk management Authors: Shishehgarkhaneh, M.; Moehler, R.C.; Fang, Y.; Aboutorab, H.; Hijazi, A.A. Score: 0.5283 ----------------- Rank #2 Potongan Chunk: are contrasted we present an integrative research typology for xai in scm to better align how scm literature has conceived ai deployment in scm this far the typology should help us understand... Title: towards explainable artificial intelligence xai in supply chain management a typology and research agenda Authors: Mugurusi, G.; Oluka, P.N. Score: 0.4893 ----------------- Rank #3 Potongan Chunk: the research using artificial intelligence ai applications in hrm functional areas has gained much traction and a steep surge over the last three years the extant literature observes that contemporary ai applications... Title: aiaugmented hrm literature review and a proposed multilevel framework for future research Authors: Prikshat, V.; Islam, M.; Patel, P.; Malik, A.; Budhwar, P.; Gupta, S. Score: 0.4782 | H12: 0.444 | I12: 0.597 | J12: 1 | K12: 1 | L12: =IMAGE("https://drive.google.com/uc?export=view&id=1jYSdCJkyV8nELiXcu9pwlF1VWnGLMdsh")
A13: 12 | B13: LaBSE | C13: 32 | D13: 3 | E13: What are the historical trends in data sources used for AI-based SCRM? | F13: Direct Summary: Historical trends in data sources used for AI-based Supply Chain Risk Management (SCRM) are not explicitly discussed in the provided documents. However, we can infer some information from the literature reviews. Detailed Synthesis: Doc [3] by Gayialis et al. (2024) provides a structured literature review on the intersection of AI and ML in SCRM, but it does not specifically discuss historical trends in data sources. Doc [1] by van Nguyen et al. (2018) reviews the application of Big Data Analytics (BDA) in SCRM, but it focuses on the areas and levels of analytics, rather than data sources. Doc [2] by Brandtner et al. (2021) explores the applications of BDA in SCRM through expert interviews, but it does not provide information on historical trends in data sources. Analysis grounded in primary sources: [van Nguyen et al., 2018; Brandtner et al., 2021; Gayialis et al., 2024]. | G13: Rank #1 Potongan Chunk: research questions 1 in what areas of scm is bda being applied 2 at what level of analytics is bda used in these scm areas 3 what types of bda models are... Title: big data analytics in supply chain management a stateoftheart literature review Authors: van Nguyen, T.; Zhou, L.; Spiegler, V.; Ieromonachou, P.; Lin, Y. Score: 0.5348 ----------------- Rank #2 Potongan Chunk: the main aim is to identify i a definition of big data from scm practitioners point of view ii current scm activities and processes where bd is already used in practice iii... Title: applications of big data analytics in supply chain management findings from expert interviews Authors: Brandtner, P.; Udokwu, C.; Darbanian, F.; Falatouri, T. Score: 0.5146 ----------------- Rank #3 Potongan Chunk: frequency numerically and using bibliometric analysis and network visualization the trends of scm research and the most prevalent ai and ml approaches were outlined the results demonstrated increased research activity after 2019... Title: exploring the intersection of artificial intelligence and machine learning in supply chain management a structured literature review Authors: Gayialis, S.P.; Kechagias, E.P.; Panayiotou, N.A.; Papadopoulos, G.A.; Papaioannou, A. Score: 0.4993 | H13: 0.889 | I13: 0 | J13: 0 | K13: 0.667 | L13: =IMAGE("https://drive.google.com/uc?export=view&id=10g3KSphlYmmWl8uVd0ORoR48gg0P6sTO")
A14: 13 | B14: LaBSE | C14: 32 | D14: 3 | E14: How has research emphasis shifted from cost efficiency to resilience? | F14: Direct Summary: Research emphasis has shifted from cost efficiency to resilience, as evident in studies focusing on sustainability and smart warehousing, such as enhancing warehouse picking efficiency and AI implementations on circular economy. This shift is driven by the need to reduce operational costs and promote resource efficiency, reuse, and recycling. Detailed Synthesis: Doc [2] highlights the importance of improving logistics performance by enhancing picking efficiency, which is essential for reducing operational costs and promoting sustainability [1]. Doc [3] explores how AI technologies can support the transition to a circular economy by promoting resource efficiency, reuse, and recycling [2]. Analysis grounded in primary sources: [Bashatah, J.A.; Elnaggar, G.R., 2025; Tongyodkaew, P.; Songmuang, P., 2025]. | G14: Rank #1 Potongan Chunk: purpose this study aimed to 1 examine ai capabilitys effect on business model design focusing on novelty and efficiency 2 explore how customer integration moderates the relationship between ai capability and novelty... Title: enhancing ai capability through supplier and customer integration in manufacturing Authors: Zhong, D.; Um, K.-H. Score: 0.4698 ----------------- Rank #2 Potongan Chunk: in logistics performance improving picking efficiency is therefore essential not only for reducing operational costs but also for enhancing resilience and sustainability in logistics this study investigates the combined impact of storage... Title: enhancing warehouse picking efficiency through integrated allocation and routing policies a case study towards sustainable and smart warehousing Authors: Bashatah, J.A.; Elnaggar, G.R. Score: 0.4565 ----------------- Rank #3 Potongan Chunk: the transition from a linear to a circular economy ce emphasizes sustainable production and consumption by promoting resource efficiency reuse and recycling this systematic literature review explores how artificial intelligence ai technologies... Title: ai implementations on circular economy a systematic literature review Authors: Tongyodkaew, P.; Songmuang, P. Score: 0.4404 | H14: 0.75 | I14: 0.502 | J14: 0.583 | K14: 1 | L14: =IMAGE("https://drive.google.com/uc?export=view&id=1x9x1EkcTn2q_uQpxpPUFwF-P0iO-XqjN")
A15: 14 | B15: LaBSE | C15: 32 | D15: 3 | E15: What temporal patterns exist in AI-driven disruption prediction studies? | F15: Direct Summary: Temporal patterns in AI-driven disruption prediction studies involve analyzing the timing and frequency of disruptions, which can be influenced by various factors such as seasonal trends, holidays, and global events. Long-term dependencies and intermittent time series are crucial aspects to consider in these studies. The accuracy of disruption prediction can be improved by leveraging deep learning architectures that excel at handling these temporal patterns. Detailed Synthesis: According to Doc [1], Transformer models are well-suited for handling long-term dependencies in time series data, which is essential for disruption prediction studies [1]. As mentioned in Doc [3], Intermittent time series can significantly impact the accuracy of disruption prediction, and global deep learning models can help mitigate these effects [3]. Analysis grounded in primary sources: [Kim et al., 2025; Flyckt & Lavesson, 2025]. | G15: Rank #1 Potongan Chunk: time series forecasting problems however the structural limitations caused by the inductive biases of each deep learning architecture constrained their performance transformer models which excel at handling longterm dependencies have become significant... Title: a comprehensive survey of deep learning for time series forecasting architectural diversity and open challenges Authors: Kim, J.; Kim, H.; Kim, H.; Lee, D.; Yoon, S. Score: 0.4720 ----------------- Rank #2 Potongan Chunk: certain time methods artificial intelligence ai technologies are suitable methods for forecasting demand the more accurate this forecast is the better it will be to decide on the management of drug production... Title: isfahan artificial intelligence event 2023 drug demand forecasting Authors: Jahani, M.; Zojaji, Z.; Montazerolghaem, A.; Palhang, M.; Ramezani, R.; Golkarnoor, A.; Safaei, A.A.; Bahak, H.; Saboori, P.; Halaj, B.S.; Naghsh-Nilchi, A.R.; Mohamadpoor, F.; Jafarizadeh, S. Score: 0.4634 ----------------- Rank #3 Potongan Chunk: timing of intermittent forecasts as well as a deeper insight into the effects of global deep learning timeseries models we perform a pilot experiment using demand forecasting in a purchasing decision support... Title: navigating demand forecasting in maketoorder manufacturing the role of global models and intermittent timeseries Authors: Flyckt, J.; Lavesson, N. Score: 0.4617 | H15: 0.786 | I15: 0.867 | J15: 0 | K15: 0.5 | L15: =IMAGE("https://drive.google.com/uc?export=view&id=1v3vDBi_Tto_l9g1pufR3eisWwi3JIw52")
A16: 15 | B16: LaBSE | C16: 32 | D16: 3 | E16: How did reinforcement learning enter supply chain resilience research? | F16: Direct Summary: Reinforcement learning has not been explicitly mentioned in the provided context data as a method for enhancing supply chain resilience. However, the integration of artificial intelligence (AI) in supply chain management is discussed in Doc [3], which may be a related area of research. Detailed Synthesis: Doc [3] by Wang (2024) explores the efficiency of supply chains embedded with AI, but does not specifically mention reinforcement learning. The provided context data does not contain any information on the application of reinforcement learning in supply chain resilience research. Analysis grounded in primary sources: [Wang, 2024], [Santos et al., 2025], [Ghorbal et al., 2025]. | G16: Rank #1 Potongan Chunk: this systematic review explores the integration of business intelligence and operations research in supply chain management the study investigates how operations research enhances business intelligence capabilities in supply chain management by providing... Title: business intelligence and operations research in supply chain management a systematic review Authors: Santos, D.; Marques, R.P. Score: 0.5301 ----------------- Rank #2 Potongan Chunk: this paper examines how integrating knowledge management km into the metaverse can enhance supply chain resilience using the analytic hierarchy process ahp the study identifies and prioritizes key supply chain challenges including... Title: enhancing supply chain resilience through knowledge management in the metaverse Authors: Ghorbal, A.; Philippot, A.; Ben Abdelaziz, F.B.; Jalaguier, C. Score: 0.5198 ----------------- Rank #3 Potongan Chunk: to help enterprises improve their sustainable development as well as the competition ability in their supply chain a research is conducted on the efficiency of the supply chain embedded with artificial intelligence... Title: linking ai supply chain strength to sustainable development and innovation a countrylevel analysis Authors: Wang, H. Score: 0.5159 | H16: 1 | I16: 0 | J16: 0 | K16: 0.6 | L16: =IMAGE("https://drive.google.com/uc?export=view&id=1LwhIqBgkAyCQ8maH4JVJ5YAyeYkgQh71")
